<?xml version="1.0" ?>
<!-- This file was autogenerated but we have modified quite a bit
Authors: Karl, Ankur

Karl did the dynamics compensation and obtained the following values for the index finger

Noise: 0.111576
Masses: 0.005, 0.125164, 0.131691, 0.0211922,
Rotor Inertia: 0.00386572, 0.00346965, 0.00433775, 0.00366413,
Viscous Friction: 0.0414019, 0.00587541, 0.010638, 0.0226948,
Coulomb Friction: 0.0523963, 0.0150275, 0.00616359, 0.0227036,
Mass Inertia:
5.1458e-05, 5.1458e-05, 6.125e-05, 0, 0, 0,
6.39979e-06, 8.88687e-05, 9.13751e-05, -3.26531e-06, 1.23963e-05, 2.07384e-05,
7.04217e-05, 3.95744e-05, 6.61125e-05, -9.64342e-05, 5.8796e-05, -3.62996e-05,
2.93743e-05, 7.21391e-05, 7.59731e-05, -3.51896e-05, -6.31225e-05, -9.25392e-07,

Center of Mass:
0, 0, 0,
0.027, 0, 0,
0.038, 0, 0,
0.029, 0, 0,

-->

<robot name="xarm7_allegro" xmlns:xacro="http://www.ros.org/wiki/xacro">
  <material name="Black">
    <color rgba="0.0 0.0 0.0 1.0"/>
  </material>
  <material name="Blue">
    <color rgba="0.0 0.0 0.8 1.0"/>
  </material>
  <material name="Green">
    <color rgba="0.0 0.8 0.0 1.0"/>
  </material>
  <material name="Grey">
    <color rgba="0.4 0.4 0.4 1.0"/>
  </material>
  <material name="Orange">
    <color rgba="1.0 0.423529411765 0.0392156862745 1.0"/>
  </material>
  <material name="Brown">
    <color rgba="0.870588235294 0.811764705882 0.764705882353 1.0"/>
  </material>
  <material name="Red">
    <color rgba="0.8 0.0 0.0 1.0"/>
  </material>
  <material name="White">
    <color rgba="1.0 1.0 1.0 1.0"/>
  </material>

  <link name="link0">
    <inertial>
      <origin rpy="0 0 0" xyz="-0.021131 -0.0016302 0.056488"/>
      <mass value="0.88556"/>
      <inertia ixx="0.0030595" ixy="0.00012259" ixz="-0.00062705" iyy="0.0037783" iyz="0.00027023" izz="0.0020125"/>
    </inertial>
    <visual>
      <geometry>
        <mesh filename="devel/kuka_allegro_description/meshes/xarm7/meshes/visual/link_base.obj"/>
      </geometry>
      <origin rpy="0 0 0" xyz="0 0 0"/>
    </visual>
    <collision>
      <geometry>
        <mesh filename="devel/kuka_allegro_description/meshes/xarm7/meshes/collision/link_base.obj"/>
      </geometry>
      <origin rpy="0 0 0" xyz="0 0 0"/>
    </collision>
  </link>
  <link name="link1">
    <inertial>
      <origin rpy="0 0 0" xyz="-0.0002 0.02905 -0.01233"/>
      <mass value="2.382"/>
      <inertia ixx="0.0056905" ixy="-1.579e-05" ixz="5.125e-06" iyy="0.0049566" iyz="-0.000873378" izz="0.003316654"/>
    </inertial>
    <visual>
      <geometry>
        <mesh filename="devel/kuka_allegro_description/meshes/xarm7/meshes/visual/link1.obj"/>
      </geometry>
      <origin rpy="0 0 0" xyz="0 0 0"/>
    </visual>
    <collision>
      <geometry>
        <mesh filename="devel/kuka_allegro_description/meshes/xarm7/meshes/collision/link1.obj"/>
      </geometry>
      <origin rpy="0 0 0" xyz="0 0 0"/>
    </collision>
  </link>
  <joint name="joint1" type="revolute">
    <origin rpy="0 0 0" xyz="0 0 0.267"/>
    <parent link="link0"/>
    <child link="link1"/>
    <axis xyz="0 0 1"/>
    <limit effort="50" lower="-6.28318530718" upper="6.28318530718" velocity="3.14"/>
    <dynamics damping="10" friction="1"/>
  </joint>
  <link name="link2">
    <inertial>
      <origin rpy="0 0 0" xyz="0.00022 -0.12856 0.01735"/>
      <mass value="1.869"/>
      <inertia ixx="0.0095989" ixy="1.541e-06" ixz="5.56e-06" iyy="0.00382472" iyz="-0.00317156" izz="0.007565669"/>
    </inertial>
    <visual>
      <geometry>
        <mesh filename="devel/kuka_allegro_description/meshes/xarm7/meshes/visual/link2.obj"/>
      </geometry>
      <origin rpy="0 0 0" xyz="0 0 0"/>
    </visual>
    <collision>
      <geometry>
        <mesh filename="devel/kuka_allegro_description/meshes/xarm7/meshes/collision/link2.obj"/>
      </geometry>
      <origin rpy="0 0 0" xyz="0 0 0"/>
    </collision>
  </link>
  <joint name="joint2" type="revolute">
    <origin rpy="-1.5708 0 0" xyz="0 0 0"/>
    <parent link="link1"/>
    <child link="link2"/>
    <axis xyz="0 0 1"/>
    <limit effort="50" lower="-2.059" upper="2.0944" velocity="3.14"/>
    <dynamics damping="10" friction="1"/>
  </joint>
  <link name="link3">
    <inertial>
      <origin rpy="0 0 0" xyz="0.0466 -0.02463 -0.00768"/>
      <mass value="1.6383"/>
      <inertia ixx="0.00310955" ixy="0.00030837" ixz="-0.00058453" iyy="0.00264483" iyz="0.000338893" izz="0.0026624"/>
    </inertial>
    <visual>
      <geometry>
        <mesh filename="devel/kuka_allegro_description/meshes/xarm7/meshes/visual/link3.obj"/>
      </geometry>
      <origin rpy="0 0 0" xyz="0 0 0"/>
    </visual>
    <collision>
      <geometry>
        <mesh filename="devel/kuka_allegro_description/meshes/xarm7/meshes/collision/link3.obj"/>
      </geometry>
      <origin rpy="0 0 0" xyz="0 0 0"/>
    </collision>
  </link>
  <joint name="joint3" type="revolute">
    <origin rpy="1.5708 0 0" xyz="0 -0.293 0"/>
    <parent link="link2"/>
    <child link="link3"/>
    <axis xyz="0 0 1"/>
    <limit effort="30" lower="-6.28318530718" upper="6.28318530718" velocity="3.14"/>
    <dynamics damping="5" friction="1"/>
  </joint>
  <link name="link4">
    <inertial>
      <origin rpy="0 0 0" xyz="0.07047 -0.11575 0.012"/>
      <mass value="1.7269"/>
      <inertia ixx="0.005889" ixy="0.00137112" ixz="0.00088143" iyy="0.00359703" iyz="-0.001762155" izz="0.00543244"/>
    </inertial>
    <visual>
      <geometry>
        <mesh filename="devel/kuka_allegro_description/meshes/xarm7/meshes/visual/link4.obj"/>
      </geometry>
      <origin rpy="0 0 0" xyz="0 0 0"/>
    </visual>
    <collision>
      <geometry>
        <mesh filename="devel/kuka_allegro_description/meshes/xarm7/meshes/collision/link4.obj"/>
      </geometry>
      <origin rpy="0 0 0" xyz="0 0 0"/>
    </collision>
  </link>
  <joint name="joint4" type="revolute">
    <origin rpy="1.5708 0 0" xyz="0.0525 0 0"/>
    <parent link="link3"/>
    <child link="link4"/>
    <axis xyz="0 0 1"/>
    <limit effort="30" lower="-0.19198" upper="3.927" velocity="3.14"/>
    <dynamics damping="5" friction="1"/>
  </joint>
  <link name="link5">
    <inertial>
      <origin rpy="0 0 0" xyz="-0.00032 0.01604 -0.026"/>
      <mass value="1.3203"/>
      <inertia ixx="0.00534665" ixy="1.5117e-05" ixz="-3.69e-07" iyy="0.0049779" iyz="-0.00022132" izz="0.0013624"/>
    </inertial>
    <visual>
      <geometry>
        <mesh filename="devel/kuka_allegro_description/meshes/xarm7/meshes/visual/link5.obj"/>
      </geometry>
      <origin rpy="0 0 0" xyz="0 0 0"/>
    </visual>
    <collision>
      <geometry>
        <mesh filename="devel/kuka_allegro_description/meshes/xarm7/meshes/collision/link5.obj"/>
      </geometry>
      <origin rpy="0 0 0" xyz="0 0 0"/>
    </collision>
  </link>
  <joint name="joint5" type="revolute">
    <origin rpy="1.5708 0 0" xyz="0.0775 -0.3425 0"/>
    <parent link="link4"/>
    <child link="link5"/>
    <axis xyz="0 0 1"/>
    <limit effort="30" lower="-6.28318530718" upper="6.28318530718" velocity="3.14"/>
    <dynamics damping="5" friction="1"/>
  </joint>
  <link name="link6">
    <inertial>
      <origin rpy="0 0 0" xyz="0.06469 0.03278 0.02141"/>
      <mass value="1.325"/>
      <inertia ixx="0.0014745" ixy="-0.000488" ixz="0.0002953" iyy="0.0019037" iyz="0.00014749" izz="0.0023652"/>
    </inertial>
    <visual>
      <geometry>
        <mesh filename="devel/kuka_allegro_description/meshes/xarm7/meshes/visual/link6.obj"/>
      </geometry>
      <origin rpy="0 0 0" xyz="0 0 0"/>
    </visual>
    <collision>
      <geometry>
        <mesh filename="devel/kuka_allegro_description/meshes/xarm7/meshes/collision/link6.obj"/>
      </geometry>
      <origin rpy="0 0 0" xyz="0 0 0"/>
    </collision>
  </link>
  <joint name="joint6" type="revolute">
    <origin rpy="1.5708 0 0" xyz="0 0 0"/>
    <parent link="link5"/>
    <child link="link6"/>
    <axis xyz="0 0 1"/>
    <limit effort="20" lower="-1.69297" upper="3.14159265359" velocity="3.14"/>
    <dynamics damping="2" friction="1"/>
  </joint>
  <link name="link7">
    <inertial>
      <origin rpy="0 0 0" xyz="0 -0.00677 -0.01098"/>
      <mass value="0.17"/>
      <inertia ixx="9.3e-05" ixy="-0.0" ixz="-0.0" iyy="5.87e-05" iyz="-3.6e-06" izz="0.000132"/>
    </inertial>
    <visual>
      <geometry>
        <mesh filename="devel/kuka_allegro_description/meshes/xarm7/meshes/visual/link7.obj"/>
      </geometry>
      <origin rpy="0 0 0" xyz="0 0 0"/>
    </visual>
    <collision>
      <geometry>
        <mesh filename="devel/kuka_allegro_description/meshes/xarm7/meshes/collision/link7.obj"/>
      </geometry>
      <origin rpy="0 0 0" xyz="0 0 0"/>
    </collision>
  </link>
  <joint name="joint7" type="revolute">
    <origin rpy="-1.5708 0 0" xyz="0.076 0.097 0"/>
    <parent link="link6"/>
    <child link="link7"/>
    <axis xyz="0 0 1"/>
    <limit effort="20" lower="-6.28318530718" upper="6.28318530718" velocity="3.14"/>
    <dynamics damping="2" friction="1"/>
  </joint>


  <joint name="allegro_mount_joint" type="fixed">
    <!-- <origin xyz="0.065 0 0.0275" rpy="0 1.57 0" /> -->
    <origin rpy="0 0 3.141592" xyz="0 -0.02 0.107"/>
    <parent link="link7"/>
    <child link="hand_base_link"/>
  </joint>


  
  <link name="hand_base_link">
    <inertial>
      <mass value="0.4154"/>
      <origin rpy="0 0 0" xyz="0 0 0"/>
      <inertia ixx="1e-4" ixy="0" ixz="0" iyy="1e-4" iyz="0" izz="1e-4"/>
    </inertial>
    <visual>
      <geometry>
        <mesh filename="devel/kuka_allegro_description/meshes/visual/base_link.glb"/>
      </geometry>
      <origin rpy="0 0 0" xyz="0 0 0 "/>
    </visual>
    <collision>
      <origin rpy="0 0 0" xyz="-0.009 0.0 -0.023"/>
      <geometry>
        <box size="0.0414 0.112 0.0448"/>
      </geometry>
    </collision>
    <collision>
      <origin rpy="0 0 0" xyz="-0.009 -0.0253 -0.0667"/>
      <geometry>
        <box size="0.0414 0.0538 0.0428"/>
      </geometry>
    </collision>
    <collision>
      <origin rpy="0 0 0" xyz="-0.009300 -0.00557 -0.08874"/>
      <geometry>
        <box size="0.0414 0.0720 0.013"/>
      </geometry>
    </collision>
  </link> <!--  virtual link-->

  <link name="wrist"/>

  <link name="palm"/>

  <joint name="wrist_joint" type="fixed">
    <origin rpy="0 0 0" xyz="0 0 -0.03"/>
    <parent link="palm"/>
    <child link="wrist"/>
  </joint>

  <joint name="palm_joint" type="fixed">
    <parent link="hand_base_link"/>
    <child link="palm"/>
    <origin rpy="0.00000 -0.00000 0.00000" xyz="0 0 -0.065"/>
  </joint> <!--  virtual link-->
  
  

  <link name="index_link_0">
    <visual>
      <geometry>
        <mesh filename="devel/kuka_allegro_description/meshes/visual/index_link_0.glb"/>
      </geometry>
    </visual>
    <collision>
      <geometry>
        <box size="0.0196 0.0275 0.0164"/>
      </geometry>
      <origin rpy="0 0 0" xyz="0 0 0.0082"/>
    </collision>
    <inertial>
      <mass value="0.0119"/>
      <origin xyz="0 0 0" rpy="0 0 0"/>
      <inertia ixx="1.01666658333e-06" ixy="0.0" ixz="0.0" iyy="6.47677333333e-07" iyz="0.0" izz="1.01666658333e-06"/>
    </inertial>
  </link>



  <joint name="index_joint_0" type="revolute">
    <axis xyz="0 0 1"/>
    <limit effort="10" lower="-0.47" upper="0.47" velocity="3.14"/>
    <parent link="hand_base_link"/>
    <child link="index_link_0"/>
    <origin rpy="-0.08726646255 0 0" xyz="0 0.0435 -0.001542"/>
  </joint>
  <link name="index_link_1">
    <inertial>
      <mass value="0.065"/>
      <origin xyz="0 0 0" rpy="0 0 0"/>
      <inertia ixx="7.95654166667e-05" ixy="1.7199e-05" ixz="8.75875e-06" iyy="2.47088833333e-05" iyz="2.413125e-05" izz="7.95654166667e-05"/>
    </inertial>
    <visual>
      <geometry>
        <mesh filename="devel/kuka_allegro_description/meshes/visual/index_link_1.glb"/>
      </geometry>
    </visual>
    <collision>
      <geometry>
        <box size="0.0196 0.0275 0.054"/>
      </geometry>
      <origin rpy="0 0 0" xyz="0 0 0.027"/>
    </collision>
  </link>
  <joint name="index_joint_1" type="revolute">
    <limit effort="10" lower="-0.196" upper="1.61" velocity="3.14"/>
    <axis xyz="0 1 0"/>
    <parent link="index_link_0"/>
    <child link="index_link_1"/>
    <origin xyz="0 0 0.0164"/>
  </joint>
  <link name="index_link_2">
    <inertial>
      <mass value="0.0355"/>
      <origin xyz="0 0 0" rpy="0 0 0"/>
      <inertia ixx="2.63979183333e-05" ixy="6.67968e-06" ixz="4.783625e-06" iyy="1.34948516667e-05" iyz="9.372e-06" izz="2.63979183333e-05"/>
    </inertial>
    <visual>
      <geometry>
        <mesh filename="devel/kuka_allegro_description/meshes/visual/index_link_2.glb"/>
      </geometry>
    </visual>
    <collision>
      <geometry>
        <box size="0.0196 0.0275 0.0384"/>
      </geometry>
      <origin rpy="0 0 0" xyz="0 0 0.0192"/>
    </collision>
  </link>
  <joint name="index_joint_2" type="revolute">
    <axis xyz="0 1 0"/>
    <limit effort="10" lower="-0.174" upper="1.709" velocity="3.14"/>
    <parent link="index_link_1"/>
    <child link="index_link_2"/>
    <origin xyz="0 0 0.054"/>
  </joint>
  <link name="index_link_3">
    <visual>
      <geometry>
        <mesh filename="devel/kuka_allegro_description/meshes/visual/index_link_3.glb"/>
      </geometry>
    </visual>
    <collision>
      <geometry>
        <box size="0.0196 0.0269 0.022"/>
      </geometry>
      <origin rpy="0 0 0" xyz="0 0 0.0047"/>
    </collision>
    <inertial>
      <origin rpy="0 0 0" xyz="0 0 0.01335"/>
      <mass value="0.02"/>
      <inertia ixx="1e-5" ixy="0.0" ixz="0.0" iyy="2e-5" iyz="0.0" izz="2e-5"/>
    </inertial>
  </link>
  <joint name="index_joint_3" type="revolute">
    <axis xyz="0 1 0"/>
    <limit effort="10" lower="-0.227" upper="1.618" velocity="3.14"/>
    <parent link="index_link_2"/>
    <child link="index_link_3"/>
    <origin xyz="0 0 0.0384"/>
  </joint>
  <link name="index_link_tip">
    <inertial>
      <mass value="0.0168"/>
      <origin xyz="0 0 0" rpy="0 0 0"/>
      <inertia ixx="9.68e-07" ixy="0" ixz="0" iyy="9.68e-07" iyz="0" izz="9.68e-07"/>
    </inertial>
    <visual>
      <origin rpy="0 0 0" xyz="0 0 -0.012"/>
      <geometry>
        <mesh filename="devel/kuka_allegro_description/meshes/visual/link_tip.glb"/>
      </geometry>
    </visual>
    <collision>
      <origin rpy="0 0 0" xyz="0 0 -0.012"/>
      <geometry>
        <mesh filename="devel/kuka_allegro_description/meshes/collision/link_tip.obj"/>
      </geometry>
    </collision>
  </link>
  <joint name="index_joint_tip" type="fixed">
    <parent link="index_link_3"/>
    <child link="index_link_tip"/>
    <origin rpy="0 0 0" xyz="0 0 0.0387"/>
  </joint>
  <link name="middle_link_0">
    <inertial>
      <mass value="0.005"/>
      <origin xyz="0 0 0"/>
      <inertia ixx="5.1458e-05" iyy="5.1458e-05" izz="6.125e-05" ixy="0" ixz="0" iyz="0"/>
    </inertial>
    <visual>
      <geometry>
        <mesh filename="devel/kuka_allegro_description/meshes/visual/index_link_0.glb"/>
      </geometry>
    </visual>
    <collision>
      <geometry>
        <box size="0.0196 0.0275 0.0164"/>
      </geometry>
      <origin rpy="0 0 0" xyz="0 0 0.0082"/>
    </collision>
  </link>
  <joint name="middle_joint_0" type="revolute">
    <axis xyz="0 0 1"/>
    <limit effort="10" lower="-0.47" upper="0.47" velocity="3.14"/>
    <parent link="hand_base_link"/>
    <child link="middle_link_0"/>
    <origin rpy="0.0 0 0" xyz="0 0 0.0007"/>
  </joint>
  <link name="middle_link_1">
    <inertial>
      <mass value="0.065"/>
      <origin xyz="0 0 0" rpy="0 0 0"/>
      <inertia ixx="7.95654166667e-05" ixy="1.7199e-05" ixz="8.75875e-06" iyy="2.47088833333e-05" iyz="2.413125e-05" izz="7.95654166667e-05"/>
    </inertial>
    <visual>
      <geometry>
        <mesh filename="devel/kuka_allegro_description/meshes/visual/index_link_1.glb"/>
      </geometry>
    </visual>
    <collision>
      <geometry>
        <box size="0.0196 0.0275 0.054"/>
      </geometry>
      <origin rpy="0 0 0" xyz="0 0 0.027"/>
    </collision>
  </link>
  <joint name="middle_joint_1" type="revolute">
    <limit effort="10" lower="-0.196" upper="1.61" velocity="3.14"/>
    <axis xyz="0 1 0"/>
    <parent link="middle_link_0"/>
    <child link="middle_link_1"/>
    <origin xyz="0 0 0.0164"/>
  </joint>
  <link name="middle_link_2">
    <inertial>
      <mass value="0.0355"/>
      <origin xyz="0 0 0" rpy="0 0 0"/>
      <inertia ixx="2.63979183333e-05" ixy="6.67968e-06" ixz="4.783625e-06" iyy="1.34948516667e-05" iyz="9.372e-06" izz="2.63979183333e-05"/>
    </inertial>
    <visual>
      <geometry>
        <mesh filename="devel/kuka_allegro_description/meshes/visual/index_link_2.glb"/>
      </geometry>
    </visual>
    <collision>
      <geometry>
        <box size="0.0196 0.0275 0.0384"/>
      </geometry>
      <origin rpy="0 0 0" xyz="0 0 0.0192"/>
    </collision>
  </link>
  <joint name="middle_joint_2" type="revolute">
    <axis xyz="0 1 0"/>
    <limit effort="10" lower="-0.174" upper="1.709" velocity="3.14"/>
    <parent link="middle_link_1"/>
    <child link="middle_link_2"/>
    <origin xyz="0 0 0.054"/>
  </joint>
  <link name="middle_link_3">
    <inertial>
      <mass value="0.0388"/>
      <origin xyz="0 0 0" rpy="0 0 0"/>
      <inertia ixx="3.29223173333e-05" ixy="8.042076e-06" ixz="5.2283e-06" iyy="1.47493026667e-5" iyz="1.1283525e-5" izz="3.29223173333e-05"/>
    </inertial>
    <visual>
      <geometry>
        <mesh filename="devel/kuka_allegro_description/meshes/visual/index_link_3.glb"/>
      </geometry>
    </visual>
    <collision>
      <geometry>
        <box size="0.0196 0.0269 0.022"/>
      </geometry>
      <origin rpy="0 0 0" xyz="0 0 0.0047"/>
    </collision>
  </link>
  <joint name="middle_joint_3" type="revolute">
    <axis xyz="0 1 0"/>
    <limit effort="10" lower="-0.227" upper="1.618" velocity="3.14"/>
    <parent link="middle_link_2"/>
    <child link="middle_link_3"/>
    <origin xyz="0 0 0.0384"/>
  </joint>
  <link name="middle_link_tip">
    <inertial>
      <mass value="0.0096"/>
      <origin xyz="0 0 0" rpy="0 0 0"/>
      <inertia ixx="4.701248e-06" ixy="1.255968e-06" ixz="1.2936e-06" iyy="3.649312e-06" iyz="1.7622e-06" izz="4.701248e-06"/>
    </inertial>
    <visual>
      <origin rpy="0 0 0" xyz="0 0 -0.012"/>
      <geometry>
        <mesh filename="devel/kuka_allegro_description/meshes/visual/link_tip.glb"/>
      </geometry>
    </visual>
    <collision>
      <origin rpy="0 0 0" xyz="0 0 -0.012"/>
      <geometry>
        <mesh filename="devel/kuka_allegro_description/meshes/collision/link_tip.obj"/>
      </geometry>
    </collision>
  </link>
  <joint name="middle_joint_tip" type="fixed">
    <parent link="middle_link_3"/>
    <child link="middle_link_tip"/>
    <origin rpy="0 0 0" xyz="0 0 0.0387"/>
  </joint>
  <link name="ring_link_0">
    <inertial>
      <mass value="0.005"/>
      <origin xyz="0 0 0"/>
      <inertia ixx="5.1458e-05" iyy="5.1458e-05" izz="6.125e-05" ixy="0" ixz="0" iyz="0"/>
    </inertial>
    <visual>
      <geometry>
        <mesh filename="devel/kuka_allegro_description/meshes/visual/index_link_0.glb"/>
      </geometry>
    </visual>
    <collision>
      <geometry>
        <box size="0.0196 0.0275 0.0164"/>
      </geometry>
      <origin rpy="0 0 0" xyz="0 0 0.0082"/>
    </collision>
  </link>
  <joint name="ring_joint_0" type="revolute">
    <axis xyz="0 0 1"/>
    <limit effort="10" lower="-0.47" upper="0.47" velocity="3.14"/>
    <parent link="hand_base_link"/>
    <child link="ring_link_0"/>
    <origin rpy="0.08726646255 0 0" xyz="0 -0.0435 -0.001542"/>
  </joint>
  <link name="ring_link_1">
    <inertial>
      <mass value="0.065"/>
      <origin xyz="0 0 0" rpy="0 0 0"/>
      <inertia ixx="7.95654166667e-05" ixy="1.7199e-05" ixz="8.75875e-06" iyy="2.47088833333e-05" iyz="2.413125e-05" izz="7.95654166667e-05"/>
    </inertial>
    <visual>
      <geometry>
        <mesh filename="devel/kuka_allegro_description/meshes/visual/index_link_1.glb"/>
      </geometry>
    </visual>
    <collision>
      <geometry>
        <box size="0.0196 0.0275 0.054"/>
      </geometry>
      <origin rpy="0 0 0" xyz="0 0 0.027"/>
    </collision>
  </link>
  <joint name="ring_joint_1" type="revolute">
    <limit effort="10" lower="-0.196" upper="1.61" velocity="3.14"/>
    <axis xyz="0 1 0"/>
    <parent link="ring_link_0"/>
    <child link="ring_link_1"/>
    <origin xyz="0 0 0.0164"/>
  </joint>
  <link name="ring_link_2">
    <inertial>
      <mass value="0.0355"/>
      <origin xyz="0 0 0" rpy="0 0 0"/>
      <inertia ixx="2.63979183333e-05" ixy="6.67968e-06" ixz="4.783625e-06" iyy="1.34948516667e-05" iyz="9.372e-06" izz="2.63979183333e-05"/>
    </inertial>
    <visual>
      <geometry>
        <mesh filename="devel/kuka_allegro_description/meshes/visual/index_link_2.glb"/>
      </geometry>
    </visual>
    <collision>
      <geometry>
        <box size="0.0196 0.0275 0.0384"/>
      </geometry>
      <origin rpy="0 0 0" xyz="0 0 0.0192"/>
    </collision>
  </link>
  <joint name="ring_joint_2" type="revolute">
    <axis xyz="0 1 0"/>
    <limit effort="10" lower="-0.174" upper="1.709" velocity="3.14"/>
    <parent link="ring_link_1"/>
    <child link="ring_link_2"/>
    <origin xyz="0 0 0.054"/>
  </joint>
  <link name="ring_link_3">
    <inertial>
      <mass value="0.0096"/>
      <origin xyz="0 0 0" rpy="0 0 0"/>
      <inertia ixx="4.701248e-06" ixy="1.255968e-06" ixz="1.2936e-06" iyy="3.649312e-06" iyz="1.7622e-06" izz="4.701248e-06"/>
    </inertial>
    <visual>
      <geometry>
        <mesh filename="devel/kuka_allegro_description/meshes/visual/index_link_3.glb"/>
      </geometry>
    </visual>
    <collision>
      <geometry>
        <box size="0.0196 0.0269 0.022"/>
      </geometry>
      <origin rpy="0 0 0" xyz="0 0 0.0047"/>
    </collision>
  </link>
  <joint name="ring_joint_3" type="revolute">
    <axis xyz="0 1 0"/>
    <limit effort="10" lower="-0.227" upper="1.618" velocity="3.14"/>
    <parent link="ring_link_2"/>
    <child link="ring_link_3"/>
    <origin xyz="0 0 0.0384"/>
  </joint>
  <link name="ring_link_tip">
    <inertial>
      <mass value="0.0168"/>
      <origin xyz="0 0 0" rpy="0 0 0"/>
      <inertia ixx="9.68e-07" ixy="0" ixz="0" iyy="9.68e-07" iyz="0" izz="9.68e-07"/>
    </inertial>
    <visual>
      <origin rpy="0 0 0" xyz="0 0 -0.012"/>
      <geometry>
        <mesh filename="devel/kuka_allegro_description/meshes/visual/link_tip.glb"/>
      </geometry>
    </visual>
    <collision>
      <origin rpy="0 0 0" xyz="0 0 -0.012"/>
      <geometry>
        <mesh filename="devel/kuka_allegro_description/meshes/collision/link_tip.obj"/>
      </geometry>
    </collision>
  </link>
  <joint name="ring_joint_tip" type="fixed">
    <parent link="ring_link_3"/>
    <child link="ring_link_tip"/>
    <origin rpy="0 0 0" xyz="0 0 0.0387"/>
  </joint> <!-- THUMB -->
  <link name="thumb_link_0">
    <inertial>
      <mass value="0.0176"/>
      <origin xyz="0 0 0" rpy="0 0 0"/>
      <inertia ixx="1.89273333333e-5" ixy="7.16716e-06" ixz="5.35568e-06" iyy="1.43008213333e-05" iyz="6.8068e-06" izz="1.89273333333e-05"/>
    </inertial>
    <visual>
      <geometry>
        <mesh filename="devel/kuka_allegro_description/meshes/visual/thumb_link_0_right.glb"/>
      </geometry>
    </visual>
    <collision>
      <geometry>
        <box size="0.0358 0.034 0.0455"/>
      </geometry>
      <origin rpy="0 0 0" xyz="-0.0179 0.009 0.0145"/>
    </collision>
  </link>
  <joint name="thumb_joint_0" type="revolute">
    <axis xyz="-1 0 0"/>
    <limit effort="10" lower="0.263" upper="1.396" velocity="3.14"/>
    <parent link="hand_base_link"/>
    <child link="thumb_link_0"/>
    <origin rpy="0 -1.65806278845 -1.5707963259" xyz="-0.0182 0.019333 -0.045987"/>
  </joint>
  <link name="thumb_link_1">
    <inertial>
      <mass value="0.0119"/>
      <origin xyz="0 0 0" rpy="0 0 0"/>
      <inertia ixx="4.24250866667e-06" ixy="1.032087e-06" ixz="1.603525e-06" iyy="4.52362633333e-06" iyz="1.44808125e-06" izz="4.24250866667e-06"/>
    </inertial>
    <visual>
      <geometry>
        <mesh filename="devel/kuka_allegro_description/meshes/visual/thumb_link_1.glb"/>
      </geometry>
    </visual>
    <collision>
      <geometry>
        <box size="0.0196 0.0275 0.0177"/>
      </geometry>
      <origin rpy="0 0 0" xyz="0 0 0.00885"/>
    </collision>
  </link>
  <joint name="thumb_joint_1" type="revolute">
    <axis xyz="0 0 1"/>
    <limit effort="10" lower="-0.105" upper="1.163" velocity="3.14"/>
    <parent link="thumb_link_0"/>
    <child link="thumb_link_1"/>
    <origin xyz="-0.027 0.005 0.0399"/>
  </joint>
  <link name="thumb_link_2">
    <inertial>
      <mass value="0.038"/>
      <origin xyz="0 0 0" rpy="0 0 0"/>
      <inertia ixx="4.30439933333e-05" ixy="9.57068e-06" ixz="5.1205e-06" iyy="1.44451933333e-05" iyz="1.342825e-05" izz="4.30439933333e-05"/>
    </inertial>
    <visual>
      <geometry>
        <mesh filename="devel/kuka_allegro_description/meshes/visual/thumb_link_2.glb"/>
      </geometry>
    </visual>
    <collision>
      <geometry>
        <box size="0.0196 0.0275 0.0514"/>
      </geometry>
      <origin rpy="0 0 0" xyz="0 0 0.0257"/>
    </collision>
  </link>
  <joint name="thumb_joint_2" type="revolute">
    <axis xyz="0 1 0"/>
    <limit effort="10" lower="-0.189" upper="1.644" velocity="3.14"/>
    <parent link="thumb_link_1"/>
    <child link="thumb_link_2"/>
    <origin xyz="0 0 0.0177"/>
  </joint>
  <link name="thumb_link_3">
    <inertial>
      <mass value="0.0388"/>
      <origin xyz="0 0 0" rpy="0 0 0"/>
      <inertia ixx="3.29223173333e-05" ixy="8.042076e-06" ixz="5.2283e-06" iyy="1.47493026667e-5" iyz="1.1283525e-5" izz="3.29223173333e-05"/>
    </inertial>
    <visual>
      <geometry>
        <mesh filename="devel/kuka_allegro_description/meshes/visual/thumb_link_3.glb"/>
      </geometry>
    </visual>
    <collision>
      <geometry>
        <box size="0.0196 0.0269 0.04"/>
      </geometry>
      <origin rpy="0 0 0" xyz="0 0 0.01125"/>
    </collision>
  </link>
  <joint name="thumb_joint_3" type="revolute">
    <axis xyz="0 1 0"/>
    <limit effort="10" lower="-0.162" upper="1.719" velocity="3.14"/>
    <parent link="thumb_link_2"/>
    <child link="thumb_link_3"/>
    <origin xyz="0 0 0.0514"/>
  </joint>
  <link name="thumb_link_tip">
    <inertial>
      <mass value="0.0168"/>
      <origin xyz="0 0 0" rpy="0 0 0"/>
      <inertia ixx="9.68e-07" ixy="0" ixz="0" iyy="9.68e-07" iyz="0" izz="9.68e-07"/>
    </inertial>
    <visual>
      <origin rpy="0 0 0" xyz="0 0 -0.012"/>
      <geometry>
        <mesh filename="devel/kuka_allegro_description/meshes/visual/link_tip.glb"/>
      </geometry>
    </visual>
    <collision>
      <origin rpy="0 0 0" xyz="0 0 -0.012"/>
      <geometry>
        <mesh filename="devel/kuka_allegro_description/meshes/collision/link_tip.obj"/>
      </geometry>
    </collision>
  </link>
  <joint name="thumb_joint_tip" type="fixed">
    <parent link="thumb_link_3"/>
    <child link="thumb_link_tip"/>
    <origin rpy="0 0 0" xyz="0 0 0.0543"/>
  </joint>


  
</robot>
